[2024-05-14T05:12:07.505+0000] {local_task_job_runner.py:120} INFO - ::group::Pre task execution logs
[2024-05-14T05:12:07.545+0000] {taskinstance.py:2076} INFO - Dependencies all met for dep_context=non-requeueable deps ti=<TaskInstance: tugas_workflow_v1.task_4 scheduled__2023-10-23T00:00:00+00:00 [queued]>
[2024-05-14T05:12:07.560+0000] {taskinstance.py:2076} INFO - Dependencies all met for dep_context=requeueable deps ti=<TaskInstance: tugas_workflow_v1.task_4 scheduled__2023-10-23T00:00:00+00:00 [queued]>
[2024-05-14T05:12:07.562+0000] {taskinstance.py:2306} INFO - Starting attempt 3 of 6
[2024-05-14T05:12:07.592+0000] {taskinstance.py:2330} INFO - Executing <Task(BashOperator): task_4> on 2023-10-23 00:00:00+00:00
[2024-05-14T05:12:07.608+0000] {warnings.py:110} WARNING - /home/***/.local/lib/python3.12/site-packages/***/task/task_runner/standard_task_runner.py:61: DeprecationWarning: This process (pid=1283) is multi-threaded, use of fork() may lead to deadlocks in the child.
  pid = os.fork()

[2024-05-14T05:12:07.612+0000] {standard_task_runner.py:63} INFO - Started process 1305 to run task
[2024-05-14T05:12:07.611+0000] {standard_task_runner.py:90} INFO - Running: ['***', 'tasks', 'run', 'tugas_workflow_v1', 'task_4', 'scheduled__2023-10-23T00:00:00+00:00', '--job-id', '166', '--raw', '--subdir', 'DAGS_FOLDER/__pycache__/prioritas_1.py', '--cfg-path', '/tmp/tmpuo0xpwfe']
[2024-05-14T05:12:07.616+0000] {standard_task_runner.py:91} INFO - Job 166: Subtask task_4
[2024-05-14T05:12:07.700+0000] {task_command.py:426} INFO - Running <TaskInstance: tugas_workflow_v1.task_4 scheduled__2023-10-23T00:00:00+00:00 [running]> on host 0391a550332e
[2024-05-14T05:12:07.822+0000] {taskinstance.py:2648} INFO - Exporting env vars: AIRFLOW_CTX_DAG_OWNER='sinta' AIRFLOW_CTX_DAG_ID='tugas_workflow_v1' AIRFLOW_CTX_TASK_ID='task_4' AIRFLOW_CTX_EXECUTION_DATE='2023-10-23T00:00:00+00:00' AIRFLOW_CTX_TRY_NUMBER='3' AIRFLOW_CTX_DAG_RUN_ID='scheduled__2023-10-23T00:00:00+00:00'
[2024-05-14T05:12:07.827+0000] {taskinstance.py:430} INFO - ::endgroup::
[2024-05-14T05:12:07.829+0000] {subprocess.py:63} INFO - Tmp dir root location: /tmp
[2024-05-14T05:12:07.831+0000] {subprocess.py:75} INFO - Running command: ['/usr/bin/bash', '-c', 'touch about_us/about.txt']
[2024-05-14T05:12:07.857+0000] {subprocess.py:86} INFO - Output:
[2024-05-14T05:12:07.861+0000] {subprocess.py:93} INFO - touch: cannot touch 'about_us/about.txt': No such file or directory
[2024-05-14T05:12:07.862+0000] {subprocess.py:97} INFO - Command exited with return code 1
[2024-05-14T05:12:07.863+0000] {taskinstance.py:441} INFO - ::group::Post task execution logs
[2024-05-14T05:12:07.885+0000] {taskinstance.py:2905} ERROR - Task failed with exception
Traceback (most recent call last):
  File "/home/airflow/.local/lib/python3.12/site-packages/airflow/models/taskinstance.py", line 465, in _execute_task
    result = _execute_callable(context=context, **execute_callable_kwargs)
             ^^^^^^^^^^^^^^^^^^^^^^^^^^^^^^^^^^^^^^^^^^^^^^^^^^^^^^^^^^^^^
  File "/home/airflow/.local/lib/python3.12/site-packages/airflow/models/taskinstance.py", line 432, in _execute_callable
    return execute_callable(context=context, **execute_callable_kwargs)
           ^^^^^^^^^^^^^^^^^^^^^^^^^^^^^^^^^^^^^^^^^^^^^^^^^^^^^^^^^^^^
  File "/home/airflow/.local/lib/python3.12/site-packages/airflow/models/baseoperator.py", line 400, in wrapper
    return func(self, *args, **kwargs)
           ^^^^^^^^^^^^^^^^^^^^^^^^^^^
  File "/home/airflow/.local/lib/python3.12/site-packages/airflow/operators/bash.py", line 243, in execute
    raise AirflowException(
airflow.exceptions.AirflowException: Bash command failed. The command returned a non-zero exit code 1.
[2024-05-14T05:12:07.891+0000] {taskinstance.py:1206} INFO - Marking task as UP_FOR_RETRY. dag_id=tugas_workflow_v1, task_id=task_4, run_id=scheduled__2023-10-23T00:00:00+00:00, execution_date=20231023T000000, start_date=20240514T051207, end_date=20240514T051207
[2024-05-14T05:12:07.916+0000] {standard_task_runner.py:110} ERROR - Failed to execute job 166 for task task_4 (Bash command failed. The command returned a non-zero exit code 1.; 1305)
[2024-05-14T05:12:07.951+0000] {local_task_job_runner.py:240} INFO - Task exited with return code 1
[2024-05-14T05:12:07.983+0000] {local_task_job_runner.py:222} INFO - ::endgroup::
