[2024-05-14T05:18:15.563+0000] {local_task_job_runner.py:120} INFO - ::group::Pre task execution logs
[2024-05-14T05:18:15.585+0000] {taskinstance.py:2076} INFO - Dependencies all met for dep_context=non-requeueable deps ti=<TaskInstance: tugas_workflow_v1.task_4 scheduled__2023-10-23T00:00:00+00:00 [queued]>
[2024-05-14T05:18:15.592+0000] {taskinstance.py:2076} INFO - Dependencies all met for dep_context=requeueable deps ti=<TaskInstance: tugas_workflow_v1.task_4 scheduled__2023-10-23T00:00:00+00:00 [queued]>
[2024-05-14T05:18:15.594+0000] {taskinstance.py:2306} INFO - Starting attempt 6 of 6
[2024-05-14T05:18:15.615+0000] {taskinstance.py:2330} INFO - Executing <Task(BashOperator): task_4> on 2023-10-23 00:00:00+00:00
[2024-05-14T05:18:15.625+0000] {warnings.py:110} WARNING - /home/***/.local/lib/python3.12/site-packages/***/task/task_runner/standard_task_runner.py:61: DeprecationWarning: This process (pid=2027) is multi-threaded, use of fork() may lead to deadlocks in the child.
  pid = os.fork()

[2024-05-14T05:18:15.627+0000] {standard_task_runner.py:63} INFO - Started process 2029 to run task
[2024-05-14T05:18:15.626+0000] {standard_task_runner.py:90} INFO - Running: ['***', 'tasks', 'run', 'tugas_workflow_v1', 'task_4', 'scheduled__2023-10-23T00:00:00+00:00', '--job-id', '331', '--raw', '--subdir', 'DAGS_FOLDER/__pycache__/prioritas_1.py', '--cfg-path', '/tmp/tmpkgopzr1n']
[2024-05-14T05:18:15.629+0000] {standard_task_runner.py:91} INFO - Job 331: Subtask task_4
[2024-05-14T05:18:15.681+0000] {task_command.py:426} INFO - Running <TaskInstance: tugas_workflow_v1.task_4 scheduled__2023-10-23T00:00:00+00:00 [running]> on host 0391a550332e
[2024-05-14T05:18:15.765+0000] {taskinstance.py:2648} INFO - Exporting env vars: AIRFLOW_CTX_DAG_OWNER='sinta' AIRFLOW_CTX_DAG_ID='tugas_workflow_v1' AIRFLOW_CTX_TASK_ID='task_4' AIRFLOW_CTX_EXECUTION_DATE='2023-10-23T00:00:00+00:00' AIRFLOW_CTX_TRY_NUMBER='6' AIRFLOW_CTX_DAG_RUN_ID='scheduled__2023-10-23T00:00:00+00:00'
[2024-05-14T05:18:15.767+0000] {taskinstance.py:430} INFO - ::endgroup::
[2024-05-14T05:18:15.769+0000] {subprocess.py:63} INFO - Tmp dir root location: /tmp
[2024-05-14T05:18:15.770+0000] {subprocess.py:75} INFO - Running command: ['/usr/bin/bash', '-c', 'touch about_us/about.txt']
[2024-05-14T05:18:15.784+0000] {subprocess.py:86} INFO - Output:
[2024-05-14T05:18:15.786+0000] {subprocess.py:93} INFO - touch: cannot touch 'about_us/about.txt': No such file or directory
[2024-05-14T05:18:15.787+0000] {subprocess.py:97} INFO - Command exited with return code 1
[2024-05-14T05:18:15.788+0000] {taskinstance.py:441} INFO - ::group::Post task execution logs
[2024-05-14T05:18:15.799+0000] {taskinstance.py:2905} ERROR - Task failed with exception
Traceback (most recent call last):
  File "/home/airflow/.local/lib/python3.12/site-packages/airflow/models/taskinstance.py", line 465, in _execute_task
    result = _execute_callable(context=context, **execute_callable_kwargs)
             ^^^^^^^^^^^^^^^^^^^^^^^^^^^^^^^^^^^^^^^^^^^^^^^^^^^^^^^^^^^^^
  File "/home/airflow/.local/lib/python3.12/site-packages/airflow/models/taskinstance.py", line 432, in _execute_callable
    return execute_callable(context=context, **execute_callable_kwargs)
           ^^^^^^^^^^^^^^^^^^^^^^^^^^^^^^^^^^^^^^^^^^^^^^^^^^^^^^^^^^^^
  File "/home/airflow/.local/lib/python3.12/site-packages/airflow/models/baseoperator.py", line 400, in wrapper
    return func(self, *args, **kwargs)
           ^^^^^^^^^^^^^^^^^^^^^^^^^^^
  File "/home/airflow/.local/lib/python3.12/site-packages/airflow/operators/bash.py", line 243, in execute
    raise AirflowException(
airflow.exceptions.AirflowException: Bash command failed. The command returned a non-zero exit code 1.
[2024-05-14T05:18:15.804+0000] {taskinstance.py:1206} INFO - Marking task as FAILED. dag_id=tugas_workflow_v1, task_id=task_4, run_id=scheduled__2023-10-23T00:00:00+00:00, execution_date=20231023T000000, start_date=20240514T051815, end_date=20240514T051815
[2024-05-14T05:18:15.819+0000] {standard_task_runner.py:110} ERROR - Failed to execute job 331 for task task_4 (Bash command failed. The command returned a non-zero exit code 1.; 2029)
[2024-05-14T05:18:15.842+0000] {local_task_job_runner.py:240} INFO - Task exited with return code 1
[2024-05-14T05:18:15.859+0000] {taskinstance.py:3498} INFO - 0 downstream tasks scheduled from follow-on schedule check
[2024-05-14T05:18:15.863+0000] {local_task_job_runner.py:222} INFO - ::endgroup::
