[2024-05-14T05:16:44.262+0000] {local_task_job_runner.py:120} INFO - ::group::Pre task execution logs
[2024-05-14T05:16:44.291+0000] {taskinstance.py:2076} INFO - Dependencies all met for dep_context=non-requeueable deps ti=<TaskInstance: tugas_workflow_v1.task_5 scheduled__2023-11-11T00:00:00+00:00 [queued]>
[2024-05-14T05:16:44.301+0000] {taskinstance.py:2076} INFO - Dependencies all met for dep_context=requeueable deps ti=<TaskInstance: tugas_workflow_v1.task_5 scheduled__2023-11-11T00:00:00+00:00 [queued]>
[2024-05-14T05:16:44.301+0000] {taskinstance.py:2306} INFO - Starting attempt 1 of 6
[2024-05-14T05:16:44.318+0000] {taskinstance.py:2330} INFO - Executing <Task(BashOperator): task_5> on 2023-11-11 00:00:00+00:00
[2024-05-14T05:16:44.328+0000] {warnings.py:110} WARNING - /home/***/.local/lib/python3.12/site-packages/***/task/task_runner/standard_task_runner.py:61: DeprecationWarning: This process (pid=1866) is multi-threaded, use of fork() may lead to deadlocks in the child.
  pid = os.fork()

[2024-05-14T05:16:44.330+0000] {standard_task_runner.py:63} INFO - Started process 1870 to run task
[2024-05-14T05:16:44.329+0000] {standard_task_runner.py:90} INFO - Running: ['***', 'tasks', 'run', 'tugas_workflow_v1', 'task_5', 'scheduled__2023-11-11T00:00:00+00:00', '--job-id', '295', '--raw', '--subdir', 'DAGS_FOLDER/__pycache__/prioritas_1.py', '--cfg-path', '/tmp/tmpr33c1qs_']
[2024-05-14T05:16:44.332+0000] {standard_task_runner.py:91} INFO - Job 295: Subtask task_5
[2024-05-14T05:16:44.391+0000] {task_command.py:426} INFO - Running <TaskInstance: tugas_workflow_v1.task_5 scheduled__2023-11-11T00:00:00+00:00 [running]> on host 0391a550332e
[2024-05-14T05:16:44.483+0000] {taskinstance.py:2648} INFO - Exporting env vars: AIRFLOW_CTX_DAG_OWNER='sinta' AIRFLOW_CTX_DAG_ID='tugas_workflow_v1' AIRFLOW_CTX_TASK_ID='task_5' AIRFLOW_CTX_EXECUTION_DATE='2023-11-11T00:00:00+00:00' AIRFLOW_CTX_TRY_NUMBER='1' AIRFLOW_CTX_DAG_RUN_ID='scheduled__2023-11-11T00:00:00+00:00'
[2024-05-14T05:16:44.485+0000] {taskinstance.py:430} INFO - ::endgroup::
[2024-05-14T05:16:44.486+0000] {subprocess.py:63} INFO - Tmp dir root location: /tmp
[2024-05-14T05:16:44.487+0000] {subprocess.py:75} INFO - Running command: ['/usr/bin/bash', '-c', 'touch our_works/works.txt']
[2024-05-14T05:16:44.503+0000] {subprocess.py:86} INFO - Output:
[2024-05-14T05:16:44.506+0000] {subprocess.py:93} INFO - touch: cannot touch 'our_works/works.txt': No such file or directory
[2024-05-14T05:16:44.506+0000] {subprocess.py:97} INFO - Command exited with return code 1
[2024-05-14T05:16:44.508+0000] {taskinstance.py:441} INFO - ::group::Post task execution logs
[2024-05-14T05:16:44.519+0000] {taskinstance.py:2905} ERROR - Task failed with exception
Traceback (most recent call last):
  File "/home/airflow/.local/lib/python3.12/site-packages/airflow/models/taskinstance.py", line 465, in _execute_task
    result = _execute_callable(context=context, **execute_callable_kwargs)
             ^^^^^^^^^^^^^^^^^^^^^^^^^^^^^^^^^^^^^^^^^^^^^^^^^^^^^^^^^^^^^
  File "/home/airflow/.local/lib/python3.12/site-packages/airflow/models/taskinstance.py", line 432, in _execute_callable
    return execute_callable(context=context, **execute_callable_kwargs)
           ^^^^^^^^^^^^^^^^^^^^^^^^^^^^^^^^^^^^^^^^^^^^^^^^^^^^^^^^^^^^
  File "/home/airflow/.local/lib/python3.12/site-packages/airflow/models/baseoperator.py", line 400, in wrapper
    return func(self, *args, **kwargs)
           ^^^^^^^^^^^^^^^^^^^^^^^^^^^
  File "/home/airflow/.local/lib/python3.12/site-packages/airflow/operators/bash.py", line 243, in execute
    raise AirflowException(
airflow.exceptions.AirflowException: Bash command failed. The command returned a non-zero exit code 1.
[2024-05-14T05:16:44.525+0000] {taskinstance.py:1206} INFO - Marking task as UP_FOR_RETRY. dag_id=tugas_workflow_v1, task_id=task_5, run_id=scheduled__2023-11-11T00:00:00+00:00, execution_date=20231111T000000, start_date=20240514T051644, end_date=20240514T051644
[2024-05-14T05:16:44.539+0000] {standard_task_runner.py:110} ERROR - Failed to execute job 295 for task task_5 (Bash command failed. The command returned a non-zero exit code 1.; 1870)
[2024-05-14T05:16:44.584+0000] {local_task_job_runner.py:240} INFO - Task exited with return code 1
[2024-05-14T05:16:44.594+0000] {local_task_job_runner.py:222} INFO - ::endgroup::
