[2024-05-20T08:31:45.997+0000] {task_context_logger.py:104} ERROR - Executor reports task instance <TaskInstance: fetch_api_data_and_write_to_files.write_to_txt scheduled__2024-05-14T00:00:00+00:00 [queued]> finished (failed) although the task says it's queued. (Info: None) Was the task killed externally?
