[2024-05-14T05:23:18.051+0000] {local_task_job_runner.py:120} INFO - ::group::Pre task execution logs
[2024-05-14T05:23:18.097+0000] {taskinstance.py:2076} INFO - Dependencies all met for dep_context=non-requeueable deps ti=<TaskInstance: tugas_workflow_v1.task_4 scheduled__2023-11-12T00:00:00+00:00 [queued]>
[2024-05-14T05:23:18.116+0000] {taskinstance.py:2076} INFO - Dependencies all met for dep_context=requeueable deps ti=<TaskInstance: tugas_workflow_v1.task_4 scheduled__2023-11-12T00:00:00+00:00 [queued]>
[2024-05-14T05:23:18.120+0000] {taskinstance.py:2306} INFO - Starting attempt 4 of 6
[2024-05-14T05:23:18.162+0000] {taskinstance.py:2330} INFO - Executing <Task(BashOperator): task_4> on 2023-11-12 00:00:00+00:00
[2024-05-14T05:23:18.175+0000] {warnings.py:110} WARNING - /home/***/.local/lib/python3.12/site-packages/***/task/task_runner/standard_task_runner.py:61: DeprecationWarning: This process (pid=2455) is multi-threaded, use of fork() may lead to deadlocks in the child.
  pid = os.fork()

[2024-05-14T05:23:18.177+0000] {standard_task_runner.py:90} INFO - Running: ['***', 'tasks', 'run', 'tugas_workflow_v1', 'task_4', 'scheduled__2023-11-12T00:00:00+00:00', '--job-id', '423', '--raw', '--subdir', 'DAGS_FOLDER/__pycache__/prioritas_1.py', '--cfg-path', '/tmp/tmph86kx9r_']
[2024-05-14T05:23:18.184+0000] {standard_task_runner.py:63} INFO - Started process 2460 to run task
[2024-05-14T05:23:18.187+0000] {standard_task_runner.py:91} INFO - Job 423: Subtask task_4
[2024-05-14T05:23:18.271+0000] {task_command.py:426} INFO - Running <TaskInstance: tugas_workflow_v1.task_4 scheduled__2023-11-12T00:00:00+00:00 [running]> on host 0391a550332e
[2024-05-14T05:23:18.427+0000] {taskinstance.py:2648} INFO - Exporting env vars: AIRFLOW_CTX_DAG_OWNER='sinta' AIRFLOW_CTX_DAG_ID='tugas_workflow_v1' AIRFLOW_CTX_TASK_ID='task_4' AIRFLOW_CTX_EXECUTION_DATE='2023-11-12T00:00:00+00:00' AIRFLOW_CTX_TRY_NUMBER='4' AIRFLOW_CTX_DAG_RUN_ID='scheduled__2023-11-12T00:00:00+00:00'
[2024-05-14T05:23:18.430+0000] {taskinstance.py:430} INFO - ::endgroup::
[2024-05-14T05:23:18.431+0000] {subprocess.py:63} INFO - Tmp dir root location: /tmp
[2024-05-14T05:23:18.435+0000] {subprocess.py:75} INFO - Running command: ['/usr/bin/bash', '-c', 'touch about_us/about.txt']
[2024-05-14T05:23:18.453+0000] {subprocess.py:86} INFO - Output:
[2024-05-14T05:23:18.456+0000] {subprocess.py:93} INFO - touch: cannot touch 'about_us/about.txt': No such file or directory
[2024-05-14T05:23:18.457+0000] {subprocess.py:97} INFO - Command exited with return code 1
[2024-05-14T05:23:18.458+0000] {taskinstance.py:441} INFO - ::group::Post task execution logs
[2024-05-14T05:23:18.475+0000] {taskinstance.py:2905} ERROR - Task failed with exception
Traceback (most recent call last):
  File "/home/airflow/.local/lib/python3.12/site-packages/airflow/models/taskinstance.py", line 465, in _execute_task
    result = _execute_callable(context=context, **execute_callable_kwargs)
             ^^^^^^^^^^^^^^^^^^^^^^^^^^^^^^^^^^^^^^^^^^^^^^^^^^^^^^^^^^^^^
  File "/home/airflow/.local/lib/python3.12/site-packages/airflow/models/taskinstance.py", line 432, in _execute_callable
    return execute_callable(context=context, **execute_callable_kwargs)
           ^^^^^^^^^^^^^^^^^^^^^^^^^^^^^^^^^^^^^^^^^^^^^^^^^^^^^^^^^^^^
  File "/home/airflow/.local/lib/python3.12/site-packages/airflow/models/baseoperator.py", line 400, in wrapper
    return func(self, *args, **kwargs)
           ^^^^^^^^^^^^^^^^^^^^^^^^^^^
  File "/home/airflow/.local/lib/python3.12/site-packages/airflow/operators/bash.py", line 243, in execute
    raise AirflowException(
airflow.exceptions.AirflowException: Bash command failed. The command returned a non-zero exit code 1.
[2024-05-14T05:23:18.482+0000] {taskinstance.py:1206} INFO - Marking task as UP_FOR_RETRY. dag_id=tugas_workflow_v1, task_id=task_4, run_id=scheduled__2023-11-12T00:00:00+00:00, execution_date=20231112T000000, start_date=20240514T052318, end_date=20240514T052318
[2024-05-14T05:23:18.501+0000] {standard_task_runner.py:110} ERROR - Failed to execute job 423 for task task_4 (Bash command failed. The command returned a non-zero exit code 1.; 2460)
[2024-05-14T05:23:18.528+0000] {local_task_job_runner.py:240} INFO - Task exited with return code 1
[2024-05-14T05:23:18.568+0000] {taskinstance.py:3498} INFO - 0 downstream tasks scheduled from follow-on schedule check
[2024-05-14T05:23:18.572+0000] {local_task_job_runner.py:222} INFO - ::endgroup::
