[2024-05-14T05:10:19.337+0000] {local_task_job_runner.py:120} INFO - ::group::Pre task execution logs
[2024-05-14T05:10:19.414+0000] {taskinstance.py:2076} INFO - Dependencies all met for dep_context=non-requeueable deps ti=<TaskInstance: tugas_workflow_v1.task_5 scheduled__2023-11-04T00:00:00+00:00 [queued]>
[2024-05-14T05:10:19.438+0000] {taskinstance.py:2076} INFO - Dependencies all met for dep_context=requeueable deps ti=<TaskInstance: tugas_workflow_v1.task_5 scheduled__2023-11-04T00:00:00+00:00 [queued]>
[2024-05-14T05:10:19.439+0000] {taskinstance.py:2306} INFO - Starting attempt 3 of 6
[2024-05-14T05:10:19.518+0000] {taskinstance.py:2330} INFO - Executing <Task(BashOperator): task_5> on 2023-11-04 00:00:00+00:00
[2024-05-14T05:10:19.558+0000] {warnings.py:110} WARNING - /home/***/.local/lib/python3.12/site-packages/***/task/task_runner/standard_task_runner.py:61: DeprecationWarning: This process (pid=1180) is multi-threaded, use of fork() may lead to deadlocks in the child.
  pid = os.fork()

[2024-05-14T05:10:19.582+0000] {standard_task_runner.py:63} INFO - Started process 1217 to run task
[2024-05-14T05:10:19.584+0000] {standard_task_runner.py:90} INFO - Running: ['***', 'tasks', 'run', 'tugas_workflow_v1', 'task_5', 'scheduled__2023-11-04T00:00:00+00:00', '--job-id', '148', '--raw', '--subdir', 'DAGS_FOLDER/__pycache__/prioritas_1.py', '--cfg-path', '/tmp/tmp7ous8g00']
[2024-05-14T05:10:19.609+0000] {standard_task_runner.py:91} INFO - Job 148: Subtask task_5
[2024-05-14T05:10:19.820+0000] {task_command.py:426} INFO - Running <TaskInstance: tugas_workflow_v1.task_5 scheduled__2023-11-04T00:00:00+00:00 [running]> on host 0391a550332e
[2024-05-14T05:10:20.138+0000] {taskinstance.py:2648} INFO - Exporting env vars: AIRFLOW_CTX_DAG_OWNER='sinta' AIRFLOW_CTX_DAG_ID='tugas_workflow_v1' AIRFLOW_CTX_TASK_ID='task_5' AIRFLOW_CTX_EXECUTION_DATE='2023-11-04T00:00:00+00:00' AIRFLOW_CTX_TRY_NUMBER='3' AIRFLOW_CTX_DAG_RUN_ID='scheduled__2023-11-04T00:00:00+00:00'
[2024-05-14T05:10:20.142+0000] {taskinstance.py:430} INFO - ::endgroup::
[2024-05-14T05:10:20.144+0000] {subprocess.py:63} INFO - Tmp dir root location: /tmp
[2024-05-14T05:10:20.148+0000] {subprocess.py:75} INFO - Running command: ['/usr/bin/bash', '-c', 'touch our_works/works.txt']
[2024-05-14T05:10:20.192+0000] {subprocess.py:86} INFO - Output:
[2024-05-14T05:10:20.203+0000] {subprocess.py:93} INFO - touch: cannot touch 'our_works/works.txt': No such file or directory
[2024-05-14T05:10:20.205+0000] {subprocess.py:97} INFO - Command exited with return code 1
[2024-05-14T05:10:20.207+0000] {taskinstance.py:441} INFO - ::group::Post task execution logs
[2024-05-14T05:10:20.228+0000] {taskinstance.py:2905} ERROR - Task failed with exception
Traceback (most recent call last):
  File "/home/airflow/.local/lib/python3.12/site-packages/airflow/models/taskinstance.py", line 465, in _execute_task
    result = _execute_callable(context=context, **execute_callable_kwargs)
             ^^^^^^^^^^^^^^^^^^^^^^^^^^^^^^^^^^^^^^^^^^^^^^^^^^^^^^^^^^^^^
  File "/home/airflow/.local/lib/python3.12/site-packages/airflow/models/taskinstance.py", line 432, in _execute_callable
    return execute_callable(context=context, **execute_callable_kwargs)
           ^^^^^^^^^^^^^^^^^^^^^^^^^^^^^^^^^^^^^^^^^^^^^^^^^^^^^^^^^^^^
  File "/home/airflow/.local/lib/python3.12/site-packages/airflow/models/baseoperator.py", line 400, in wrapper
    return func(self, *args, **kwargs)
           ^^^^^^^^^^^^^^^^^^^^^^^^^^^
  File "/home/airflow/.local/lib/python3.12/site-packages/airflow/operators/bash.py", line 243, in execute
    raise AirflowException(
airflow.exceptions.AirflowException: Bash command failed. The command returned a non-zero exit code 1.
[2024-05-14T05:10:20.237+0000] {taskinstance.py:1206} INFO - Marking task as UP_FOR_RETRY. dag_id=tugas_workflow_v1, task_id=task_5, run_id=scheduled__2023-11-04T00:00:00+00:00, execution_date=20231104T000000, start_date=20240514T051019, end_date=20240514T051020
[2024-05-14T05:10:20.284+0000] {standard_task_runner.py:110} ERROR - Failed to execute job 148 for task task_5 (Bash command failed. The command returned a non-zero exit code 1.; 1217)
[2024-05-14T05:10:20.332+0000] {local_task_job_runner.py:240} INFO - Task exited with return code 1
[2024-05-14T05:10:20.377+0000] {taskinstance.py:3498} INFO - 0 downstream tasks scheduled from follow-on schedule check
[2024-05-14T05:10:20.400+0000] {local_task_job_runner.py:222} INFO - ::endgroup::
