[2024-05-14T05:22:59.875+0000] {local_task_job_runner.py:120} INFO - ::group::Pre task execution logs
[2024-05-14T05:22:59.984+0000] {taskinstance.py:2076} INFO - Dependencies all met for dep_context=non-requeueable deps ti=<TaskInstance: tugas_workflow_v1.task_4 scheduled__2023-11-10T00:00:00+00:00 [queued]>
[2024-05-14T05:23:00.109+0000] {taskinstance.py:2076} INFO - Dependencies all met for dep_context=requeueable deps ti=<TaskInstance: tugas_workflow_v1.task_4 scheduled__2023-11-10T00:00:00+00:00 [queued]>
[2024-05-14T05:23:00.139+0000] {taskinstance.py:2306} INFO - Starting attempt 4 of 6
[2024-05-14T05:23:00.721+0000] {taskinstance.py:2330} INFO - Executing <Task(BashOperator): task_4> on 2023-11-10 00:00:00+00:00
[2024-05-14T05:23:00.754+0000] {warnings.py:110} WARNING - /home/***/.local/lib/python3.12/site-packages/***/task/task_runner/standard_task_runner.py:61: DeprecationWarning: This process (pid=2402) is multi-threaded, use of fork() may lead to deadlocks in the child.
  pid = os.fork()

[2024-05-14T05:23:00.720+0000] {standard_task_runner.py:63} INFO - Started process 2429 to run task
[2024-05-14T05:23:00.764+0000] {standard_task_runner.py:90} INFO - Running: ['***', 'tasks', 'run', 'tugas_workflow_v1', 'task_4', 'scheduled__2023-11-10T00:00:00+00:00', '--job-id', '412', '--raw', '--subdir', 'DAGS_FOLDER/__pycache__/prioritas_1.py', '--cfg-path', '/tmp/tmppa04858b']
[2024-05-14T05:23:00.856+0000] {standard_task_runner.py:91} INFO - Job 412: Subtask task_4
[2024-05-14T05:23:01.212+0000] {task_command.py:426} INFO - Running <TaskInstance: tugas_workflow_v1.task_4 scheduled__2023-11-10T00:00:00+00:00 [running]> on host 0391a550332e
[2024-05-14T05:23:01.716+0000] {taskinstance.py:2648} INFO - Exporting env vars: AIRFLOW_CTX_DAG_OWNER='sinta' AIRFLOW_CTX_DAG_ID='tugas_workflow_v1' AIRFLOW_CTX_TASK_ID='task_4' AIRFLOW_CTX_EXECUTION_DATE='2023-11-10T00:00:00+00:00' AIRFLOW_CTX_TRY_NUMBER='4' AIRFLOW_CTX_DAG_RUN_ID='scheduled__2023-11-10T00:00:00+00:00'
[2024-05-14T05:23:01.730+0000] {taskinstance.py:430} INFO - ::endgroup::
[2024-05-14T05:23:01.731+0000] {subprocess.py:63} INFO - Tmp dir root location: /tmp
[2024-05-14T05:23:01.745+0000] {subprocess.py:75} INFO - Running command: ['/usr/bin/bash', '-c', 'touch about_us/about.txt']
[2024-05-14T05:23:01.802+0000] {subprocess.py:86} INFO - Output:
[2024-05-14T05:23:01.812+0000] {subprocess.py:93} INFO - touch: cannot touch 'about_us/about.txt': No such file or directory
[2024-05-14T05:23:01.813+0000] {subprocess.py:97} INFO - Command exited with return code 1
[2024-05-14T05:23:01.814+0000] {taskinstance.py:441} INFO - ::group::Post task execution logs
[2024-05-14T05:23:01.843+0000] {taskinstance.py:2905} ERROR - Task failed with exception
Traceback (most recent call last):
  File "/home/airflow/.local/lib/python3.12/site-packages/airflow/models/taskinstance.py", line 465, in _execute_task
    result = _execute_callable(context=context, **execute_callable_kwargs)
             ^^^^^^^^^^^^^^^^^^^^^^^^^^^^^^^^^^^^^^^^^^^^^^^^^^^^^^^^^^^^^
  File "/home/airflow/.local/lib/python3.12/site-packages/airflow/models/taskinstance.py", line 432, in _execute_callable
    return execute_callable(context=context, **execute_callable_kwargs)
           ^^^^^^^^^^^^^^^^^^^^^^^^^^^^^^^^^^^^^^^^^^^^^^^^^^^^^^^^^^^^
  File "/home/airflow/.local/lib/python3.12/site-packages/airflow/models/baseoperator.py", line 400, in wrapper
    return func(self, *args, **kwargs)
           ^^^^^^^^^^^^^^^^^^^^^^^^^^^
  File "/home/airflow/.local/lib/python3.12/site-packages/airflow/operators/bash.py", line 243, in execute
    raise AirflowException(
airflow.exceptions.AirflowException: Bash command failed. The command returned a non-zero exit code 1.
[2024-05-14T05:23:01.880+0000] {taskinstance.py:1206} INFO - Marking task as UP_FOR_RETRY. dag_id=tugas_workflow_v1, task_id=task_4, run_id=scheduled__2023-11-10T00:00:00+00:00, execution_date=20231110T000000, start_date=20240514T052300, end_date=20240514T052301
[2024-05-14T05:23:01.950+0000] {standard_task_runner.py:110} ERROR - Failed to execute job 412 for task task_4 (Bash command failed. The command returned a non-zero exit code 1.; 2429)
[2024-05-14T05:23:02.028+0000] {local_task_job_runner.py:240} INFO - Task exited with return code 1
[2024-05-14T05:23:02.066+0000] {local_task_job_runner.py:222} INFO - ::endgroup::
