[2024-05-14T05:10:01.084+0000] {local_task_job_runner.py:120} INFO - ::group::Pre task execution logs
[2024-05-14T05:10:01.114+0000] {taskinstance.py:2076} INFO - Dependencies all met for dep_context=non-requeueable deps ti=<TaskInstance: tugas_workflow_v1.task_5 scheduled__2023-10-25T00:00:00+00:00 [queued]>
[2024-05-14T05:10:01.126+0000] {taskinstance.py:2076} INFO - Dependencies all met for dep_context=requeueable deps ti=<TaskInstance: tugas_workflow_v1.task_5 scheduled__2023-10-25T00:00:00+00:00 [queued]>
[2024-05-14T05:10:01.127+0000] {taskinstance.py:2306} INFO - Starting attempt 3 of 6
[2024-05-14T05:10:01.146+0000] {taskinstance.py:2330} INFO - Executing <Task(BashOperator): task_5> on 2023-10-25 00:00:00+00:00
[2024-05-14T05:10:01.161+0000] {warnings.py:110} WARNING - /home/***/.local/lib/python3.12/site-packages/***/task/task_runner/standard_task_runner.py:61: DeprecationWarning: This process (pid=1115) is multi-threaded, use of fork() may lead to deadlocks in the child.
  pid = os.fork()

[2024-05-14T05:10:01.163+0000] {standard_task_runner.py:63} INFO - Started process 1125 to run task
[2024-05-14T05:10:01.164+0000] {standard_task_runner.py:90} INFO - Running: ['***', 'tasks', 'run', 'tugas_workflow_v1', 'task_5', 'scheduled__2023-10-25T00:00:00+00:00', '--job-id', '128', '--raw', '--subdir', 'DAGS_FOLDER/__pycache__/prioritas_1.py', '--cfg-path', '/tmp/tmpn1opiqet']
[2024-05-14T05:10:01.168+0000] {standard_task_runner.py:91} INFO - Job 128: Subtask task_5
[2024-05-14T05:10:01.239+0000] {task_command.py:426} INFO - Running <TaskInstance: tugas_workflow_v1.task_5 scheduled__2023-10-25T00:00:00+00:00 [running]> on host 0391a550332e
[2024-05-14T05:10:01.383+0000] {taskinstance.py:2648} INFO - Exporting env vars: AIRFLOW_CTX_DAG_OWNER='sinta' AIRFLOW_CTX_DAG_ID='tugas_workflow_v1' AIRFLOW_CTX_TASK_ID='task_5' AIRFLOW_CTX_EXECUTION_DATE='2023-10-25T00:00:00+00:00' AIRFLOW_CTX_TRY_NUMBER='3' AIRFLOW_CTX_DAG_RUN_ID='scheduled__2023-10-25T00:00:00+00:00'
[2024-05-14T05:10:01.388+0000] {taskinstance.py:430} INFO - ::endgroup::
[2024-05-14T05:10:01.391+0000] {subprocess.py:63} INFO - Tmp dir root location: /tmp
[2024-05-14T05:10:01.394+0000] {subprocess.py:75} INFO - Running command: ['/usr/bin/bash', '-c', 'touch our_works/works.txt']
[2024-05-14T05:10:01.417+0000] {subprocess.py:86} INFO - Output:
[2024-05-14T05:10:01.421+0000] {subprocess.py:93} INFO - touch: cannot touch 'our_works/works.txt': No such file or directory
[2024-05-14T05:10:01.423+0000] {subprocess.py:97} INFO - Command exited with return code 1
[2024-05-14T05:10:01.424+0000] {taskinstance.py:441} INFO - ::group::Post task execution logs
[2024-05-14T05:10:01.437+0000] {taskinstance.py:2905} ERROR - Task failed with exception
Traceback (most recent call last):
  File "/home/airflow/.local/lib/python3.12/site-packages/airflow/models/taskinstance.py", line 465, in _execute_task
    result = _execute_callable(context=context, **execute_callable_kwargs)
             ^^^^^^^^^^^^^^^^^^^^^^^^^^^^^^^^^^^^^^^^^^^^^^^^^^^^^^^^^^^^^
  File "/home/airflow/.local/lib/python3.12/site-packages/airflow/models/taskinstance.py", line 432, in _execute_callable
    return execute_callable(context=context, **execute_callable_kwargs)
           ^^^^^^^^^^^^^^^^^^^^^^^^^^^^^^^^^^^^^^^^^^^^^^^^^^^^^^^^^^^^
  File "/home/airflow/.local/lib/python3.12/site-packages/airflow/models/baseoperator.py", line 400, in wrapper
    return func(self, *args, **kwargs)
           ^^^^^^^^^^^^^^^^^^^^^^^^^^^
  File "/home/airflow/.local/lib/python3.12/site-packages/airflow/operators/bash.py", line 243, in execute
    raise AirflowException(
airflow.exceptions.AirflowException: Bash command failed. The command returned a non-zero exit code 1.
[2024-05-14T05:10:01.444+0000] {taskinstance.py:1206} INFO - Marking task as UP_FOR_RETRY. dag_id=tugas_workflow_v1, task_id=task_5, run_id=scheduled__2023-10-25T00:00:00+00:00, execution_date=20231025T000000, start_date=20240514T051001, end_date=20240514T051001
[2024-05-14T05:10:01.483+0000] {standard_task_runner.py:110} ERROR - Failed to execute job 128 for task task_5 (Bash command failed. The command returned a non-zero exit code 1.; 1125)
[2024-05-14T05:10:01.546+0000] {local_task_job_runner.py:240} INFO - Task exited with return code 1
[2024-05-14T05:10:01.559+0000] {local_task_job_runner.py:222} INFO - ::endgroup::
