[2024-05-14T05:12:04.664+0000] {local_task_job_runner.py:120} INFO - ::group::Pre task execution logs
[2024-05-14T05:12:04.709+0000] {taskinstance.py:2076} INFO - Dependencies all met for dep_context=non-requeueable deps ti=<TaskInstance: tugas_workflow_v1.task_4 scheduled__2023-10-26T00:00:00+00:00 [queued]>
[2024-05-14T05:12:04.728+0000] {taskinstance.py:2076} INFO - Dependencies all met for dep_context=requeueable deps ti=<TaskInstance: tugas_workflow_v1.task_4 scheduled__2023-10-26T00:00:00+00:00 [queued]>
[2024-05-14T05:12:04.733+0000] {taskinstance.py:2306} INFO - Starting attempt 4 of 6
[2024-05-14T05:12:04.770+0000] {taskinstance.py:2330} INFO - Executing <Task(BashOperator): task_4> on 2023-10-26 00:00:00+00:00
[2024-05-14T05:12:04.797+0000] {warnings.py:110} WARNING - /home/***/.local/lib/python3.12/site-packages/***/task/task_runner/standard_task_runner.py:61: DeprecationWarning: This process (pid=1269) is multi-threaded, use of fork() may lead to deadlocks in the child.
  pid = os.fork()

[2024-05-14T05:12:04.805+0000] {standard_task_runner.py:63} INFO - Started process 1285 to run task
[2024-05-14T05:12:04.810+0000] {standard_task_runner.py:90} INFO - Running: ['***', 'tasks', 'run', 'tugas_workflow_v1', 'task_4', 'scheduled__2023-10-26T00:00:00+00:00', '--job-id', '162', '--raw', '--subdir', 'DAGS_FOLDER/__pycache__/prioritas_1.py', '--cfg-path', '/tmp/tmp95_ridsc']
[2024-05-14T05:12:04.838+0000] {standard_task_runner.py:91} INFO - Job 162: Subtask task_4
[2024-05-14T05:12:04.971+0000] {task_command.py:426} INFO - Running <TaskInstance: tugas_workflow_v1.task_4 scheduled__2023-10-26T00:00:00+00:00 [running]> on host 0391a550332e
[2024-05-14T05:12:05.273+0000] {taskinstance.py:2648} INFO - Exporting env vars: AIRFLOW_CTX_DAG_OWNER='sinta' AIRFLOW_CTX_DAG_ID='tugas_workflow_v1' AIRFLOW_CTX_TASK_ID='task_4' AIRFLOW_CTX_EXECUTION_DATE='2023-10-26T00:00:00+00:00' AIRFLOW_CTX_TRY_NUMBER='4' AIRFLOW_CTX_DAG_RUN_ID='scheduled__2023-10-26T00:00:00+00:00'
[2024-05-14T05:12:05.278+0000] {taskinstance.py:430} INFO - ::endgroup::
[2024-05-14T05:12:05.282+0000] {subprocess.py:63} INFO - Tmp dir root location: /tmp
[2024-05-14T05:12:05.284+0000] {subprocess.py:75} INFO - Running command: ['/usr/bin/bash', '-c', 'touch about_us/about.txt']
[2024-05-14T05:12:05.311+0000] {subprocess.py:86} INFO - Output:
[2024-05-14T05:12:05.320+0000] {subprocess.py:93} INFO - touch: cannot touch 'about_us/about.txt': No such file or directory
[2024-05-14T05:12:05.321+0000] {subprocess.py:97} INFO - Command exited with return code 1
[2024-05-14T05:12:05.323+0000] {taskinstance.py:441} INFO - ::group::Post task execution logs
[2024-05-14T05:12:05.360+0000] {taskinstance.py:2905} ERROR - Task failed with exception
Traceback (most recent call last):
  File "/home/airflow/.local/lib/python3.12/site-packages/airflow/models/taskinstance.py", line 465, in _execute_task
    result = _execute_callable(context=context, **execute_callable_kwargs)
             ^^^^^^^^^^^^^^^^^^^^^^^^^^^^^^^^^^^^^^^^^^^^^^^^^^^^^^^^^^^^^
  File "/home/airflow/.local/lib/python3.12/site-packages/airflow/models/taskinstance.py", line 432, in _execute_callable
    return execute_callable(context=context, **execute_callable_kwargs)
           ^^^^^^^^^^^^^^^^^^^^^^^^^^^^^^^^^^^^^^^^^^^^^^^^^^^^^^^^^^^^
  File "/home/airflow/.local/lib/python3.12/site-packages/airflow/models/baseoperator.py", line 400, in wrapper
    return func(self, *args, **kwargs)
           ^^^^^^^^^^^^^^^^^^^^^^^^^^^
  File "/home/airflow/.local/lib/python3.12/site-packages/airflow/operators/bash.py", line 243, in execute
    raise AirflowException(
airflow.exceptions.AirflowException: Bash command failed. The command returned a non-zero exit code 1.
[2024-05-14T05:12:05.374+0000] {taskinstance.py:1206} INFO - Marking task as UP_FOR_RETRY. dag_id=tugas_workflow_v1, task_id=task_4, run_id=scheduled__2023-10-26T00:00:00+00:00, execution_date=20231026T000000, start_date=20240514T051204, end_date=20240514T051205
[2024-05-14T05:12:05.481+0000] {standard_task_runner.py:110} ERROR - Failed to execute job 162 for task task_4 (Bash command failed. The command returned a non-zero exit code 1.; 1285)
[2024-05-14T05:12:05.502+0000] {local_task_job_runner.py:240} INFO - Task exited with return code 1
[2024-05-14T05:12:05.527+0000] {local_task_job_runner.py:222} INFO - ::endgroup::
