[2024-05-14T05:16:33.707+0000] {local_task_job_runner.py:120} INFO - ::group::Pre task execution logs
[2024-05-14T05:16:33.791+0000] {taskinstance.py:2076} INFO - Dependencies all met for dep_context=non-requeueable deps ti=<TaskInstance: tugas_workflow_v1.task_4 manual__2024-05-14T05:05:01.599354+00:00 [queued]>
[2024-05-14T05:16:33.806+0000] {taskinstance.py:2076} INFO - Dependencies all met for dep_context=requeueable deps ti=<TaskInstance: tugas_workflow_v1.task_4 manual__2024-05-14T05:05:01.599354+00:00 [queued]>
[2024-05-14T05:16:33.815+0000] {taskinstance.py:2306} INFO - Starting attempt 6 of 6
[2024-05-14T05:16:33.872+0000] {taskinstance.py:2330} INFO - Executing <Task(BashOperator): task_4> on 2024-05-14 05:05:01.599354+00:00
[2024-05-14T05:16:33.896+0000] {warnings.py:110} WARNING - /home/***/.local/lib/python3.12/site-packages/***/task/task_runner/standard_task_runner.py:61: DeprecationWarning: This process (pid=1748) is multi-threaded, use of fork() may lead to deadlocks in the child.
  pid = os.fork()

[2024-05-14T05:16:33.899+0000] {standard_task_runner.py:63} INFO - Started process 1787 to run task
[2024-05-14T05:16:33.911+0000] {standard_task_runner.py:90} INFO - Running: ['***', 'tasks', 'run', 'tugas_workflow_v1', 'task_4', 'manual__2024-05-14T05:05:01.599354+00:00', '--job-id', '272', '--raw', '--subdir', 'DAGS_FOLDER/__pycache__/prioritas_1.py', '--cfg-path', '/tmp/tmpe2fteif7']
[2024-05-14T05:16:33.915+0000] {standard_task_runner.py:91} INFO - Job 272: Subtask task_4
[2024-05-14T05:16:34.061+0000] {task_command.py:426} INFO - Running <TaskInstance: tugas_workflow_v1.task_4 manual__2024-05-14T05:05:01.599354+00:00 [running]> on host 0391a550332e
[2024-05-14T05:16:34.295+0000] {taskinstance.py:2648} INFO - Exporting env vars: AIRFLOW_CTX_DAG_OWNER='sinta' AIRFLOW_CTX_DAG_ID='tugas_workflow_v1' AIRFLOW_CTX_TASK_ID='task_4' AIRFLOW_CTX_EXECUTION_DATE='2024-05-14T05:05:01.599354+00:00' AIRFLOW_CTX_TRY_NUMBER='6' AIRFLOW_CTX_DAG_RUN_ID='manual__2024-05-14T05:05:01.599354+00:00'
[2024-05-14T05:16:34.302+0000] {taskinstance.py:430} INFO - ::endgroup::
[2024-05-14T05:16:34.305+0000] {subprocess.py:63} INFO - Tmp dir root location: /tmp
[2024-05-14T05:16:34.319+0000] {subprocess.py:75} INFO - Running command: ['/usr/bin/bash', '-c', 'touch about_us/about.txt']
[2024-05-14T05:16:34.386+0000] {subprocess.py:86} INFO - Output:
[2024-05-14T05:16:34.401+0000] {subprocess.py:93} INFO - touch: cannot touch 'about_us/about.txt': No such file or directory
[2024-05-14T05:16:34.402+0000] {subprocess.py:97} INFO - Command exited with return code 1
[2024-05-14T05:16:34.403+0000] {taskinstance.py:441} INFO - ::group::Post task execution logs
[2024-05-14T05:16:34.424+0000] {taskinstance.py:2905} ERROR - Task failed with exception
Traceback (most recent call last):
  File "/home/airflow/.local/lib/python3.12/site-packages/airflow/models/taskinstance.py", line 465, in _execute_task
    result = _execute_callable(context=context, **execute_callable_kwargs)
             ^^^^^^^^^^^^^^^^^^^^^^^^^^^^^^^^^^^^^^^^^^^^^^^^^^^^^^^^^^^^^
  File "/home/airflow/.local/lib/python3.12/site-packages/airflow/models/taskinstance.py", line 432, in _execute_callable
    return execute_callable(context=context, **execute_callable_kwargs)
           ^^^^^^^^^^^^^^^^^^^^^^^^^^^^^^^^^^^^^^^^^^^^^^^^^^^^^^^^^^^^
  File "/home/airflow/.local/lib/python3.12/site-packages/airflow/models/baseoperator.py", line 400, in wrapper
    return func(self, *args, **kwargs)
           ^^^^^^^^^^^^^^^^^^^^^^^^^^^
  File "/home/airflow/.local/lib/python3.12/site-packages/airflow/operators/bash.py", line 243, in execute
    raise AirflowException(
airflow.exceptions.AirflowException: Bash command failed. The command returned a non-zero exit code 1.
[2024-05-14T05:16:34.441+0000] {taskinstance.py:1206} INFO - Marking task as FAILED. dag_id=tugas_workflow_v1, task_id=task_4, run_id=manual__2024-05-14T05:05:01.599354+00:00, execution_date=20240514T050501, start_date=20240514T051633, end_date=20240514T051634
[2024-05-14T05:16:34.507+0000] {standard_task_runner.py:110} ERROR - Failed to execute job 272 for task task_4 (Bash command failed. The command returned a non-zero exit code 1.; 1787)
[2024-05-14T05:16:34.531+0000] {local_task_job_runner.py:240} INFO - Task exited with return code 1
[2024-05-14T05:16:34.596+0000] {taskinstance.py:3498} INFO - 0 downstream tasks scheduled from follow-on schedule check
[2024-05-14T05:16:34.612+0000] {local_task_job_runner.py:222} INFO - ::endgroup::
