[2024-05-14T05:10:15.799+0000] {local_task_job_runner.py:120} INFO - ::group::Pre task execution logs
[2024-05-14T05:10:15.853+0000] {taskinstance.py:2076} INFO - Dependencies all met for dep_context=non-requeueable deps ti=<TaskInstance: tugas_workflow_v1.task_4 scheduled__2023-10-30T00:00:00+00:00 [queued]>
[2024-05-14T05:10:15.876+0000] {taskinstance.py:2076} INFO - Dependencies all met for dep_context=requeueable deps ti=<TaskInstance: tugas_workflow_v1.task_4 scheduled__2023-10-30T00:00:00+00:00 [queued]>
[2024-05-14T05:10:15.878+0000] {taskinstance.py:2306} INFO - Starting attempt 3 of 6
[2024-05-14T05:10:15.921+0000] {taskinstance.py:2330} INFO - Executing <Task(BashOperator): task_4> on 2023-10-30 00:00:00+00:00
[2024-05-14T05:10:15.933+0000] {warnings.py:110} WARNING - /home/***/.local/lib/python3.12/site-packages/***/task/task_runner/standard_task_runner.py:61: DeprecationWarning: This process (pid=1171) is multi-threaded, use of fork() may lead to deadlocks in the child.
  pid = os.fork()

[2024-05-14T05:10:15.941+0000] {standard_task_runner.py:63} INFO - Started process 1187 to run task
[2024-05-14T05:10:15.947+0000] {standard_task_runner.py:90} INFO - Running: ['***', 'tasks', 'run', 'tugas_workflow_v1', 'task_4', 'scheduled__2023-10-30T00:00:00+00:00', '--job-id', '142', '--raw', '--subdir', 'DAGS_FOLDER/__pycache__/prioritas_1.py', '--cfg-path', '/tmp/tmpcxlw1bfm']
[2024-05-14T05:10:15.953+0000] {standard_task_runner.py:91} INFO - Job 142: Subtask task_4
[2024-05-14T05:10:16.074+0000] {task_command.py:426} INFO - Running <TaskInstance: tugas_workflow_v1.task_4 scheduled__2023-10-30T00:00:00+00:00 [running]> on host 0391a550332e
[2024-05-14T05:10:16.323+0000] {taskinstance.py:2648} INFO - Exporting env vars: AIRFLOW_CTX_DAG_OWNER='sinta' AIRFLOW_CTX_DAG_ID='tugas_workflow_v1' AIRFLOW_CTX_TASK_ID='task_4' AIRFLOW_CTX_EXECUTION_DATE='2023-10-30T00:00:00+00:00' AIRFLOW_CTX_TRY_NUMBER='3' AIRFLOW_CTX_DAG_RUN_ID='scheduled__2023-10-30T00:00:00+00:00'
[2024-05-14T05:10:16.338+0000] {taskinstance.py:430} INFO - ::endgroup::
[2024-05-14T05:10:16.351+0000] {subprocess.py:63} INFO - Tmp dir root location: /tmp
[2024-05-14T05:10:16.357+0000] {subprocess.py:75} INFO - Running command: ['/usr/bin/bash', '-c', 'touch about_us/about.txt']
[2024-05-14T05:10:16.413+0000] {subprocess.py:86} INFO - Output:
[2024-05-14T05:10:16.419+0000] {subprocess.py:93} INFO - touch: cannot touch 'about_us/about.txt': No such file or directory
[2024-05-14T05:10:16.420+0000] {subprocess.py:97} INFO - Command exited with return code 1
[2024-05-14T05:10:16.421+0000] {taskinstance.py:441} INFO - ::group::Post task execution logs
[2024-05-14T05:10:16.438+0000] {taskinstance.py:2905} ERROR - Task failed with exception
Traceback (most recent call last):
  File "/home/airflow/.local/lib/python3.12/site-packages/airflow/models/taskinstance.py", line 465, in _execute_task
    result = _execute_callable(context=context, **execute_callable_kwargs)
             ^^^^^^^^^^^^^^^^^^^^^^^^^^^^^^^^^^^^^^^^^^^^^^^^^^^^^^^^^^^^^
  File "/home/airflow/.local/lib/python3.12/site-packages/airflow/models/taskinstance.py", line 432, in _execute_callable
    return execute_callable(context=context, **execute_callable_kwargs)
           ^^^^^^^^^^^^^^^^^^^^^^^^^^^^^^^^^^^^^^^^^^^^^^^^^^^^^^^^^^^^
  File "/home/airflow/.local/lib/python3.12/site-packages/airflow/models/baseoperator.py", line 400, in wrapper
    return func(self, *args, **kwargs)
           ^^^^^^^^^^^^^^^^^^^^^^^^^^^
  File "/home/airflow/.local/lib/python3.12/site-packages/airflow/operators/bash.py", line 243, in execute
    raise AirflowException(
airflow.exceptions.AirflowException: Bash command failed. The command returned a non-zero exit code 1.
[2024-05-14T05:10:16.445+0000] {taskinstance.py:1206} INFO - Marking task as UP_FOR_RETRY. dag_id=tugas_workflow_v1, task_id=task_4, run_id=scheduled__2023-10-30T00:00:00+00:00, execution_date=20231030T000000, start_date=20240514T051015, end_date=20240514T051016
[2024-05-14T05:10:16.466+0000] {standard_task_runner.py:110} ERROR - Failed to execute job 142 for task task_4 (Bash command failed. The command returned a non-zero exit code 1.; 1187)
[2024-05-14T05:10:16.526+0000] {local_task_job_runner.py:240} INFO - Task exited with return code 1
[2024-05-14T05:10:16.539+0000] {local_task_job_runner.py:222} INFO - ::endgroup::
